SQLite3 message, D:\Documents\daily\E_Plus_2040_py\standalone_output\session_20250622_202250\simulation_results\building_4136733_safe_modified\sqlite.err open for processing!
